[2025-07-02T11:00:07.958+0000] {taskinstance.py:1956} INFO - Dependencies all met for dep_context=non-requeueable deps ti=<TaskInstance: transport_model_training.check_new_data scheduled__2025-07-01T00:00:00+00:00 [queued]>
[2025-07-02T11:00:07.966+0000] {taskinstance.py:1956} INFO - Dependencies all met for dep_context=requeueable deps ti=<TaskInstance: transport_model_training.check_new_data scheduled__2025-07-01T00:00:00+00:00 [queued]>
[2025-07-02T11:00:07.966+0000] {taskinstance.py:2170} INFO - Starting attempt 2 of 2
[2025-07-02T11:00:07.977+0000] {taskinstance.py:2191} INFO - Executing <Task(FileSensor): check_new_data> on 2025-07-01 00:00:00+00:00
[2025-07-02T11:00:07.982+0000] {standard_task_runner.py:60} INFO - Started process 263 to run task
[2025-07-02T11:00:07.985+0000] {standard_task_runner.py:87} INFO - Running: ['***', 'tasks', 'run', 'transport_model_training', 'check_new_data', 'scheduled__2025-07-01T00:00:00+00:00', '--job-id', '8', '--raw', '--subdir', 'DAGS_FOLDER/train_model_dag.py', '--cfg-path', '/tmp/tmpgv52x7z1']
[2025-07-02T11:00:07.986+0000] {standard_task_runner.py:88} INFO - Job 8: Subtask check_new_data
[2025-07-02T11:00:08.035+0000] {task_command.py:423} INFO - Running <TaskInstance: transport_model_training.check_new_data scheduled__2025-07-01T00:00:00+00:00 [running]> on host 41d3a1b16a2e
[2025-07-02T11:00:08.136+0000] {taskinstance.py:2480} INFO - Exporting env vars: AIRFLOW_CTX_DAG_EMAIL='hamdanialhassangandi2020@gmail.com' AIRFLOW_CTX_DAG_OWNER='ml_team' AIRFLOW_CTX_DAG_ID='transport_model_training' AIRFLOW_CTX_TASK_ID='check_new_data' AIRFLOW_CTX_EXECUTION_DATE='2025-07-01T00:00:00+00:00' AIRFLOW_CTX_TRY_NUMBER='2' AIRFLOW_CTX_DAG_RUN_ID='scheduled__2025-07-01T00:00:00+00:00'
[2025-07-02T11:00:08.152+0000] {base.py:83} INFO - Using connection ID 'fs_default' for task execution.
[2025-07-02T11:00:08.153+0000] {filesystem.py:66} INFO - Poking for file /home/lusitech/AmaliTech/ML_Transport_Accra/data/raw/new_data_flag.txt
[2025-07-02T11:05:08.261+0000] {base.py:83} INFO - Using connection ID 'fs_default' for task execution.
[2025-07-02T11:05:08.262+0000] {filesystem.py:66} INFO - Poking for file /home/lusitech/AmaliTech/ML_Transport_Accra/data/raw/new_data_flag.txt
[2025-07-02T11:10:08.369+0000] {base.py:83} INFO - Using connection ID 'fs_default' for task execution.
[2025-07-02T11:10:08.370+0000] {filesystem.py:66} INFO - Poking for file /home/lusitech/AmaliTech/ML_Transport_Accra/data/raw/new_data_flag.txt
[2025-07-02T11:15:08.477+0000] {base.py:83} INFO - Using connection ID 'fs_default' for task execution.
[2025-07-02T11:15:08.478+0000] {filesystem.py:66} INFO - Poking for file /home/lusitech/AmaliTech/ML_Transport_Accra/data/raw/new_data_flag.txt
[2025-07-02T11:20:08.588+0000] {base.py:83} INFO - Using connection ID 'fs_default' for task execution.
[2025-07-02T11:20:08.589+0000] {filesystem.py:66} INFO - Poking for file /home/lusitech/AmaliTech/ML_Transport_Accra/data/raw/new_data_flag.txt
[2025-07-02T11:25:08.699+0000] {base.py:83} INFO - Using connection ID 'fs_default' for task execution.
[2025-07-02T11:25:08.701+0000] {filesystem.py:66} INFO - Poking for file /home/lusitech/AmaliTech/ML_Transport_Accra/data/raw/new_data_flag.txt
[2025-07-02T11:30:08.806+0000] {base.py:83} INFO - Using connection ID 'fs_default' for task execution.
[2025-07-02T11:30:08.807+0000] {filesystem.py:66} INFO - Poking for file /home/lusitech/AmaliTech/ML_Transport_Accra/data/raw/new_data_flag.txt
[2025-07-02T11:35:08.919+0000] {base.py:83} INFO - Using connection ID 'fs_default' for task execution.
[2025-07-02T11:35:08.921+0000] {filesystem.py:66} INFO - Poking for file /home/lusitech/AmaliTech/ML_Transport_Accra/data/raw/new_data_flag.txt
[2025-07-02T11:40:09.034+0000] {base.py:83} INFO - Using connection ID 'fs_default' for task execution.
[2025-07-02T11:40:09.036+0000] {filesystem.py:66} INFO - Poking for file /home/lusitech/AmaliTech/ML_Transport_Accra/data/raw/new_data_flag.txt
[2025-07-02T11:45:09.086+0000] {base.py:83} INFO - Using connection ID 'fs_default' for task execution.
[2025-07-02T11:45:09.087+0000] {filesystem.py:66} INFO - Poking for file /home/lusitech/AmaliTech/ML_Transport_Accra/data/raw/new_data_flag.txt
[2025-07-02T11:50:09.194+0000] {base.py:83} INFO - Using connection ID 'fs_default' for task execution.
[2025-07-02T11:50:09.194+0000] {filesystem.py:66} INFO - Poking for file /home/lusitech/AmaliTech/ML_Transport_Accra/data/raw/new_data_flag.txt
[2025-07-02T11:55:09.300+0000] {base.py:83} INFO - Using connection ID 'fs_default' for task execution.
[2025-07-02T11:55:09.301+0000] {filesystem.py:66} INFO - Poking for file /home/lusitech/AmaliTech/ML_Transport_Accra/data/raw/new_data_flag.txt
[2025-07-02T11:55:30.951+0000] {local_task_job_runner.py:121} ERROR - Received SIGTERM. Terminating subprocesses
[2025-07-02T11:55:30.966+0000] {process_utils.py:131} INFO - Sending 15 to group 263. PIDs of all processes in the group: [263]
[2025-07-02T11:55:30.966+0000] {process_utils.py:86} INFO - Sending the signal 15 to group 263
[2025-07-02T11:55:30.967+0000] {taskinstance.py:2450} ERROR - Received SIGTERM. Terminating subprocesses.
[2025-07-02T11:55:31.021+0000] {taskinstance.py:2698} ERROR - Task failed with exception
Traceback (most recent call last):
  File "/home/airflow/.local/lib/python3.8/site-packages/airflow/models/taskinstance.py", line 433, in _execute_task
    result = execute_callable(context=context, **execute_callable_kwargs)
  File "/home/airflow/.local/lib/python3.8/site-packages/airflow/sensors/base.py", line 293, in execute
    time.sleep(self._get_next_poke_interval(started_at, run_duration, try_number))
  File "/home/airflow/.local/lib/python3.8/site-packages/airflow/models/taskinstance.py", line 2452, in signal_handler
    raise AirflowException("Task received SIGTERM signal")
airflow.exceptions.AirflowException: Task received SIGTERM signal
[2025-07-02T11:55:31.025+0000] {taskinstance.py:1138} INFO - Marking task as FAILED. dag_id=transport_model_training, task_id=check_new_data, execution_date=20250701T000000, start_date=20250702T110007, end_date=20250702T115531
[2025-07-02T11:55:31.068+0000] {logging_mixin.py:188} WARNING - /home/***/.local/lib/python3.8/site-packages/***/utils/email.py:154 RemovedInAirflow3Warning: Fetching SMTP credentials from configuration variables will be deprecated in a future release. Please set credentials using a connection instead.
[2025-07-02T11:55:31.069+0000] {configuration.py:1046} WARNING - section/key [smtp/smtp_user] not found in config
[2025-07-02T11:55:31.069+0000] {email.py:270} INFO - Email alerting: attempt 1
[2025-07-02T11:55:31.114+0000] {configuration.py:1046} WARNING - section/key [smtp/smtp_user] not found in config
[2025-07-02T11:55:31.117+0000] {email.py:270} INFO - Email alerting: attempt 1
[2025-07-02T11:55:31.119+0000] {taskinstance.py:826} ERROR - Failed to send email to: ['hamdanialhassangandi2020@gmail.com']
Traceback (most recent call last):
  File "/home/airflow/.local/lib/python3.8/site-packages/airflow/models/taskinstance.py", line 2334, in _run_raw_task
    self._execute_task_with_callbacks(context, test_mode, session=session)
  File "/home/airflow/.local/lib/python3.8/site-packages/airflow/models/taskinstance.py", line 2499, in _execute_task_with_callbacks
    result = self._execute_task(context, task_orig)
  File "/home/airflow/.local/lib/python3.8/site-packages/airflow/models/taskinstance.py", line 2516, in _execute_task
    return _execute_task(self, context, task_orig)
  File "/home/airflow/.local/lib/python3.8/site-packages/airflow/models/taskinstance.py", line 433, in _execute_task
    result = execute_callable(context=context, **execute_callable_kwargs)
  File "/home/airflow/.local/lib/python3.8/site-packages/airflow/sensors/base.py", line 293, in execute
    time.sleep(self._get_next_poke_interval(started_at, run_duration, try_number))
  File "/home/airflow/.local/lib/python3.8/site-packages/airflow/models/taskinstance.py", line 2452, in signal_handler
    raise AirflowException("Task received SIGTERM signal")
airflow.exceptions.AirflowException: Task received SIGTERM signal

During handling of the above exception, another exception occurred:

Traceback (most recent call last):
  File "/home/airflow/.local/lib/python3.8/site-packages/airflow/models/taskinstance.py", line 1000, in _email_alert
    send_email(task.email, subject, html_content)
  File "/home/airflow/.local/lib/python3.8/site-packages/airflow/utils/email.py", line 80, in send_email
    return backend(
  File "/home/airflow/.local/lib/python3.8/site-packages/airflow/utils/email.py", line 154, in send_email_smtp
    send_mime_email(e_from=mail_from, e_to=recipients, mime_msg=msg, conn_id=conn_id, dryrun=dryrun)
  File "/home/airflow/.local/lib/python3.8/site-packages/airflow/utils/email.py", line 272, in send_mime_email
    smtp_conn = _get_smtp_connection(smtp_host, smtp_port, smtp_timeout, smtp_ssl)
  File "/home/airflow/.local/lib/python3.8/site-packages/airflow/utils/email.py", line 316, in _get_smtp_connection
    return smtplib.SMTP(host=host, port=port, timeout=timeout)
  File "/usr/local/lib/python3.8/smtplib.py", line 255, in __init__
    (code, msg) = self.connect(host, port)
  File "/usr/local/lib/python3.8/smtplib.py", line 339, in connect
    self.sock = self._get_socket(host, port, self.timeout)
  File "/usr/local/lib/python3.8/smtplib.py", line 310, in _get_socket
    return socket.create_connection((host, port), timeout,
  File "/usr/local/lib/python3.8/socket.py", line 808, in create_connection
    raise err
  File "/usr/local/lib/python3.8/socket.py", line 796, in create_connection
    sock.connect(sa)
ConnectionRefusedError: [Errno 111] Connection refused

During handling of the above exception, another exception occurred:

Traceback (most recent call last):
  File "/home/airflow/.local/lib/python3.8/site-packages/airflow/models/taskinstance.py", line 824, in _handle_failure
    task_instance.email_alert(error, failure_context["task"])
  File "/home/airflow/.local/lib/python3.8/site-packages/airflow/models/taskinstance.py", line 2946, in email_alert
    _email_alert(task_instance=self, exception=exception, task=task)
  File "/home/airflow/.local/lib/python3.8/site-packages/airflow/models/taskinstance.py", line 1002, in _email_alert
    send_email(task.email, subject, html_content_err)
  File "/home/airflow/.local/lib/python3.8/site-packages/airflow/utils/email.py", line 80, in send_email
    return backend(
  File "/home/airflow/.local/lib/python3.8/site-packages/airflow/utils/email.py", line 154, in send_email_smtp
    send_mime_email(e_from=mail_from, e_to=recipients, mime_msg=msg, conn_id=conn_id, dryrun=dryrun)
  File "/home/airflow/.local/lib/python3.8/site-packages/airflow/utils/email.py", line 272, in send_mime_email
    smtp_conn = _get_smtp_connection(smtp_host, smtp_port, smtp_timeout, smtp_ssl)
  File "/home/airflow/.local/lib/python3.8/site-packages/airflow/utils/email.py", line 316, in _get_smtp_connection
    return smtplib.SMTP(host=host, port=port, timeout=timeout)
  File "/usr/local/lib/python3.8/smtplib.py", line 255, in __init__
    (code, msg) = self.connect(host, port)
  File "/usr/local/lib/python3.8/smtplib.py", line 339, in connect
    self.sock = self._get_socket(host, port, self.timeout)
  File "/usr/local/lib/python3.8/smtplib.py", line 310, in _get_socket
    return socket.create_connection((host, port), timeout,
  File "/usr/local/lib/python3.8/socket.py", line 808, in create_connection
    raise err
  File "/usr/local/lib/python3.8/socket.py", line 796, in create_connection
    sock.connect(sa)
ConnectionRefusedError: [Errno 111] Connection refused
[2025-07-02T11:55:31.166+0000] {standard_task_runner.py:107} ERROR - Failed to execute job 8 for task check_new_data (Task received SIGTERM signal; 263)
[2025-07-02T11:55:31.187+0000] {process_utils.py:79} INFO - Process psutil.Process(pid=263, status='terminated', exitcode=1, started='11:00:07') (263) terminated with exit code 1
[2025-07-02T11:55:31.189+0000] {local_task_job_runner.py:234} INFO - Task exited with return code 143
[2025-07-02T11:55:31.223+0000] {taskinstance.py:3280} INFO - 0 downstream tasks scheduled from follow-on schedule check
