[2025-07-02T11:43:45.138+0000] {taskinstance.py:1956} INFO - Dependencies all met for dep_context=non-requeueable deps ti=<TaskInstance: transport_model_training.evaluate_model manual__2025-07-02T10:44:07.832849+00:00 [queued]>
[2025-07-02T11:43:45.152+0000] {taskinstance.py:1956} INFO - Dependencies all met for dep_context=requeueable deps ti=<TaskInstance: transport_model_training.evaluate_model manual__2025-07-02T10:44:07.832849+00:00 [queued]>
[2025-07-02T11:43:45.153+0000] {taskinstance.py:2170} INFO - Starting attempt 1 of 2
[2025-07-02T11:43:45.187+0000] {taskinstance.py:2191} INFO - Executing <Task(PythonOperator): evaluate_model> on 2025-07-02 10:44:07.832849+00:00
[2025-07-02T11:43:45.203+0000] {standard_task_runner.py:60} INFO - Started process 1228 to run task
[2025-07-02T11:43:45.212+0000] {standard_task_runner.py:87} INFO - Running: ['***', 'tasks', 'run', 'transport_model_training', 'evaluate_model', 'manual__2025-07-02T10:44:07.832849+00:00', '--job-id', '14', '--raw', '--subdir', 'DAGS_FOLDER/train_model_dag.py', '--cfg-path', '/tmp/tmpvo6p9oni']
[2025-07-02T11:43:45.220+0000] {standard_task_runner.py:88} INFO - Job 14: Subtask evaluate_model
[2025-07-02T11:43:45.339+0000] {task_command.py:423} INFO - Running <TaskInstance: transport_model_training.evaluate_model manual__2025-07-02T10:44:07.832849+00:00 [running]> on host 41d3a1b16a2e
[2025-07-02T11:43:45.544+0000] {taskinstance.py:2480} INFO - Exporting env vars: AIRFLOW_CTX_DAG_EMAIL='hamdanialhassangandi2020@gmail.com' AIRFLOW_CTX_DAG_OWNER='ml_team' AIRFLOW_CTX_DAG_ID='transport_model_training' AIRFLOW_CTX_TASK_ID='evaluate_model' AIRFLOW_CTX_EXECUTION_DATE='2025-07-02T10:44:07.832849+00:00' AIRFLOW_CTX_TRY_NUMBER='1' AIRFLOW_CTX_DAG_RUN_ID='manual__2025-07-02T10:44:07.832849+00:00'
[2025-07-02T11:43:45.550+0000] {taskinstance.py:2698} ERROR - Task failed with exception
Traceback (most recent call last):
  File "/home/airflow/.local/lib/python3.8/site-packages/airflow/models/taskinstance.py", line 433, in _execute_task
    result = execute_callable(context=context, **execute_callable_kwargs)
  File "/home/airflow/.local/lib/python3.8/site-packages/airflow/operators/python.py", line 199, in execute
    return_value = self.execute_callable()
  File "/home/airflow/.local/lib/python3.8/site-packages/airflow/operators/python.py", line 216, in execute_callable
    return self.python_callable(*self.op_args, **self.op_kwargs)
  File "/opt/airflow/dags/train_model_dag.py", line 90, in evaluate
    import mlflow
ModuleNotFoundError: No module named 'mlflow'
[2025-07-02T11:43:45.566+0000] {taskinstance.py:1138} INFO - Marking task as UP_FOR_RETRY. dag_id=transport_model_training, task_id=evaluate_model, execution_date=20250702T104407, start_date=20250702T114345, end_date=20250702T114345
[2025-07-02T11:43:45.586+0000] {standard_task_runner.py:107} ERROR - Failed to execute job 14 for task evaluate_model (No module named 'mlflow'; 1228)
[2025-07-02T11:43:45.630+0000] {local_task_job_runner.py:234} INFO - Task exited with return code 1
[2025-07-02T11:43:45.670+0000] {taskinstance.py:3280} INFO - 0 downstream tasks scheduled from follow-on schedule check
