[2025-07-02T12:00:31.696+0000] {taskinstance.py:1956} INFO - Dependencies all met for dep_context=non-requeueable deps ti=<TaskInstance: transport_model_training.check_new_data manual__2025-07-02T11:46:18.943047+00:00 [queued]>
[2025-07-02T12:00:31.702+0000] {taskinstance.py:1956} INFO - Dependencies all met for dep_context=requeueable deps ti=<TaskInstance: transport_model_training.check_new_data manual__2025-07-02T11:46:18.943047+00:00 [queued]>
[2025-07-02T12:00:31.702+0000] {taskinstance.py:2170} INFO - Starting attempt 2 of 2
[2025-07-02T12:00:31.713+0000] {taskinstance.py:2191} INFO - Executing <Task(FileSensor): check_new_data> on 2025-07-02 11:46:18.943047+00:00
[2025-07-02T12:00:31.718+0000] {standard_task_runner.py:60} INFO - Started process 267 to run task
[2025-07-02T12:00:31.720+0000] {standard_task_runner.py:87} INFO - Running: ['***', 'tasks', 'run', 'transport_model_training', 'check_new_data', 'manual__2025-07-02T11:46:18.943047+00:00', '--job-id', '19', '--raw', '--subdir', 'DAGS_FOLDER/train_model_dag.py', '--cfg-path', '/tmp/tmp6itme8fx']
[2025-07-02T12:00:31.721+0000] {standard_task_runner.py:88} INFO - Job 19: Subtask check_new_data
[2025-07-02T12:00:31.758+0000] {task_command.py:423} INFO - Running <TaskInstance: transport_model_training.check_new_data manual__2025-07-02T11:46:18.943047+00:00 [running]> on host 1c07c4596c43
[2025-07-02T12:00:31.837+0000] {taskinstance.py:2480} INFO - Exporting env vars: AIRFLOW_CTX_DAG_EMAIL='hamdanialhassangandi2020@gmail.com' AIRFLOW_CTX_DAG_OWNER='ml_team' AIRFLOW_CTX_DAG_ID='transport_model_training' AIRFLOW_CTX_TASK_ID='check_new_data' AIRFLOW_CTX_EXECUTION_DATE='2025-07-02T11:46:18.943047+00:00' AIRFLOW_CTX_TRY_NUMBER='2' AIRFLOW_CTX_DAG_RUN_ID='manual__2025-07-02T11:46:18.943047+00:00'
[2025-07-02T12:00:31.849+0000] {base.py:83} INFO - Using connection ID 'fs_default' for task execution.
[2025-07-02T12:00:31.849+0000] {filesystem.py:66} INFO - Poking for file /opt/***/data/raw/new_data_flag.txt
[2025-07-02T12:05:31.962+0000] {base.py:83} INFO - Using connection ID 'fs_default' for task execution.
[2025-07-02T12:05:31.963+0000] {filesystem.py:66} INFO - Poking for file /opt/***/data/raw/new_data_flag.txt
[2025-07-02T12:10:32.075+0000] {base.py:83} INFO - Using connection ID 'fs_default' for task execution.
[2025-07-02T12:10:32.078+0000] {filesystem.py:66} INFO - Poking for file /opt/***/data/raw/new_data_flag.txt
[2025-07-02T12:15:32.187+0000] {base.py:83} INFO - Using connection ID 'fs_default' for task execution.
[2025-07-02T12:15:32.188+0000] {filesystem.py:66} INFO - Poking for file /opt/***/data/raw/new_data_flag.txt
[2025-07-02T12:20:32.297+0000] {base.py:83} INFO - Using connection ID 'fs_default' for task execution.
[2025-07-02T12:20:32.299+0000] {filesystem.py:66} INFO - Poking for file /opt/***/data/raw/new_data_flag.txt
[2025-07-02T12:25:32.411+0000] {base.py:83} INFO - Using connection ID 'fs_default' for task execution.
[2025-07-02T12:25:32.412+0000] {filesystem.py:66} INFO - Poking for file /opt/***/data/raw/new_data_flag.txt
[2025-07-02T12:30:32.523+0000] {base.py:83} INFO - Using connection ID 'fs_default' for task execution.
[2025-07-02T12:30:32.524+0000] {filesystem.py:66} INFO - Poking for file /opt/***/data/raw/new_data_flag.txt
[2025-07-02T12:35:32.635+0000] {base.py:83} INFO - Using connection ID 'fs_default' for task execution.
[2025-07-02T12:35:32.636+0000] {filesystem.py:66} INFO - Poking for file /opt/***/data/raw/new_data_flag.txt
[2025-07-02T12:40:32.748+0000] {base.py:83} INFO - Using connection ID 'fs_default' for task execution.
[2025-07-02T12:40:32.750+0000] {filesystem.py:66} INFO - Poking for file /opt/***/data/raw/new_data_flag.txt
[2025-07-02T12:45:32.861+0000] {base.py:83} INFO - Using connection ID 'fs_default' for task execution.
[2025-07-02T12:45:32.862+0000] {filesystem.py:66} INFO - Poking for file /opt/***/data/raw/new_data_flag.txt
[2025-07-02T12:50:32.973+0000] {base.py:83} INFO - Using connection ID 'fs_default' for task execution.
[2025-07-02T12:50:32.974+0000] {filesystem.py:66} INFO - Poking for file /opt/***/data/raw/new_data_flag.txt
[2025-07-02T12:55:33.085+0000] {base.py:83} INFO - Using connection ID 'fs_default' for task execution.
[2025-07-02T12:55:33.086+0000] {filesystem.py:66} INFO - Poking for file /opt/***/data/raw/new_data_flag.txt
[2025-07-02T13:00:33.197+0000] {base.py:83} INFO - Using connection ID 'fs_default' for task execution.
[2025-07-02T13:00:33.198+0000] {filesystem.py:66} INFO - Poking for file /opt/***/data/raw/new_data_flag.txt
[2025-07-02T13:00:33.199+0000] {taskinstance.py:2698} ERROR - Task failed with exception
Traceback (most recent call last):
  File "/home/airflow/.local/lib/python3.8/site-packages/airflow/models/taskinstance.py", line 433, in _execute_task
    result = execute_callable(context=context, **execute_callable_kwargs)
  File "/home/airflow/.local/lib/python3.8/site-packages/airflow/sensors/base.py", line 282, in execute
    raise AirflowSensorTimeout(message)
airflow.exceptions.AirflowSensorTimeout: Sensor has timed out; run duration of 3601.359613191 seconds exceeds the specified timeout of 3600.0.
[2025-07-02T13:00:33.210+0000] {taskinstance.py:1138} INFO - Immediate failure requested. Marking task as FAILED. dag_id=transport_model_training, task_id=check_new_data, execution_date=20250702T114618, start_date=20250702T120031, end_date=20250702T130033
[2025-07-02T13:00:33.234+0000] {logging_mixin.py:188} WARNING - /home/***/.local/lib/python3.8/site-packages/***/utils/email.py:154 RemovedInAirflow3Warning: Fetching SMTP credentials from configuration variables will be deprecated in a future release. Please set credentials using a connection instead.
[2025-07-02T13:00:33.235+0000] {configuration.py:1046} WARNING - section/key [smtp/smtp_user] not found in config
[2025-07-02T13:00:33.235+0000] {email.py:270} INFO - Email alerting: attempt 1
[2025-07-02T13:00:33.241+0000] {configuration.py:1046} WARNING - section/key [smtp/smtp_user] not found in config
[2025-07-02T13:00:33.241+0000] {email.py:270} INFO - Email alerting: attempt 1
[2025-07-02T13:00:33.242+0000] {taskinstance.py:826} ERROR - Failed to send email to: ['hamdanialhassangandi2020@gmail.com']
Traceback (most recent call last):
  File "/home/airflow/.local/lib/python3.8/site-packages/airflow/models/taskinstance.py", line 2334, in _run_raw_task
    self._execute_task_with_callbacks(context, test_mode, session=session)
  File "/home/airflow/.local/lib/python3.8/site-packages/airflow/models/taskinstance.py", line 2499, in _execute_task_with_callbacks
    result = self._execute_task(context, task_orig)
  File "/home/airflow/.local/lib/python3.8/site-packages/airflow/models/taskinstance.py", line 2516, in _execute_task
    return _execute_task(self, context, task_orig)
  File "/home/airflow/.local/lib/python3.8/site-packages/airflow/models/taskinstance.py", line 433, in _execute_task
    result = execute_callable(context=context, **execute_callable_kwargs)
  File "/home/airflow/.local/lib/python3.8/site-packages/airflow/sensors/base.py", line 282, in execute
    raise AirflowSensorTimeout(message)
airflow.exceptions.AirflowSensorTimeout: Sensor has timed out; run duration of 3601.359613191 seconds exceeds the specified timeout of 3600.0.

During handling of the above exception, another exception occurred:

Traceback (most recent call last):
  File "/home/airflow/.local/lib/python3.8/site-packages/airflow/models/taskinstance.py", line 1000, in _email_alert
    send_email(task.email, subject, html_content)
  File "/home/airflow/.local/lib/python3.8/site-packages/airflow/utils/email.py", line 80, in send_email
    return backend(
  File "/home/airflow/.local/lib/python3.8/site-packages/airflow/utils/email.py", line 154, in send_email_smtp
    send_mime_email(e_from=mail_from, e_to=recipients, mime_msg=msg, conn_id=conn_id, dryrun=dryrun)
  File "/home/airflow/.local/lib/python3.8/site-packages/airflow/utils/email.py", line 272, in send_mime_email
    smtp_conn = _get_smtp_connection(smtp_host, smtp_port, smtp_timeout, smtp_ssl)
  File "/home/airflow/.local/lib/python3.8/site-packages/airflow/utils/email.py", line 316, in _get_smtp_connection
    return smtplib.SMTP(host=host, port=port, timeout=timeout)
  File "/usr/local/lib/python3.8/smtplib.py", line 255, in __init__
    (code, msg) = self.connect(host, port)
  File "/usr/local/lib/python3.8/smtplib.py", line 339, in connect
    self.sock = self._get_socket(host, port, self.timeout)
  File "/usr/local/lib/python3.8/smtplib.py", line 310, in _get_socket
    return socket.create_connection((host, port), timeout,
  File "/usr/local/lib/python3.8/socket.py", line 808, in create_connection
    raise err
  File "/usr/local/lib/python3.8/socket.py", line 796, in create_connection
    sock.connect(sa)
ConnectionRefusedError: [Errno 111] Connection refused

During handling of the above exception, another exception occurred:

Traceback (most recent call last):
  File "/home/airflow/.local/lib/python3.8/site-packages/airflow/models/taskinstance.py", line 824, in _handle_failure
    task_instance.email_alert(error, failure_context["task"])
  File "/home/airflow/.local/lib/python3.8/site-packages/airflow/models/taskinstance.py", line 2946, in email_alert
    _email_alert(task_instance=self, exception=exception, task=task)
  File "/home/airflow/.local/lib/python3.8/site-packages/airflow/models/taskinstance.py", line 1002, in _email_alert
    send_email(task.email, subject, html_content_err)
  File "/home/airflow/.local/lib/python3.8/site-packages/airflow/utils/email.py", line 80, in send_email
    return backend(
  File "/home/airflow/.local/lib/python3.8/site-packages/airflow/utils/email.py", line 154, in send_email_smtp
    send_mime_email(e_from=mail_from, e_to=recipients, mime_msg=msg, conn_id=conn_id, dryrun=dryrun)
  File "/home/airflow/.local/lib/python3.8/site-packages/airflow/utils/email.py", line 272, in send_mime_email
    smtp_conn = _get_smtp_connection(smtp_host, smtp_port, smtp_timeout, smtp_ssl)
  File "/home/airflow/.local/lib/python3.8/site-packages/airflow/utils/email.py", line 316, in _get_smtp_connection
    return smtplib.SMTP(host=host, port=port, timeout=timeout)
  File "/usr/local/lib/python3.8/smtplib.py", line 255, in __init__
    (code, msg) = self.connect(host, port)
  File "/usr/local/lib/python3.8/smtplib.py", line 339, in connect
    self.sock = self._get_socket(host, port, self.timeout)
  File "/usr/local/lib/python3.8/smtplib.py", line 310, in _get_socket
    return socket.create_connection((host, port), timeout,
  File "/usr/local/lib/python3.8/socket.py", line 808, in create_connection
    raise err
  File "/usr/local/lib/python3.8/socket.py", line 796, in create_connection
    sock.connect(sa)
ConnectionRefusedError: [Errno 111] Connection refused
[2025-07-02T13:00:33.260+0000] {standard_task_runner.py:107} ERROR - Failed to execute job 19 for task check_new_data (Sensor has timed out; run duration of 3601.359613191 seconds exceeds the specified timeout of 3600.0.; 267)
[2025-07-02T13:00:33.280+0000] {local_task_job_runner.py:234} INFO - Task exited with return code 1
[2025-07-02T13:00:33.315+0000] {taskinstance.py:3280} INFO - 0 downstream tasks scheduled from follow-on schedule check
