[2025-07-02T14:21:20.838+0000] {taskinstance.py:1956} INFO - Dependencies all met for dep_context=non-requeueable deps ti=<TaskInstance: transport_model_training.train_model manual__2025-07-02T14:21:17.805105+00:00 [queued]>
[2025-07-02T14:21:20.845+0000] {taskinstance.py:1956} INFO - Dependencies all met for dep_context=requeueable deps ti=<TaskInstance: transport_model_training.train_model manual__2025-07-02T14:21:17.805105+00:00 [queued]>
[2025-07-02T14:21:20.846+0000] {taskinstance.py:2170} INFO - Starting attempt 1 of 2
[2025-07-02T14:21:20.857+0000] {taskinstance.py:2191} INFO - Executing <Task(PythonOperator): train_model> on 2025-07-02 14:21:17.805105+00:00
[2025-07-02T14:21:20.862+0000] {standard_task_runner.py:60} INFO - Started process 188 to run task
[2025-07-02T14:21:20.865+0000] {standard_task_runner.py:87} INFO - Running: ['***', 'tasks', 'run', 'transport_model_training', 'train_model', 'manual__2025-07-02T14:21:17.805105+00:00', '--job-id', '28', '--raw', '--subdir', 'DAGS_FOLDER/train_model_dag.py', '--cfg-path', '/tmp/tmpsw_opycy']
[2025-07-02T14:21:20.866+0000] {standard_task_runner.py:88} INFO - Job 28: Subtask train_model
[2025-07-02T14:21:20.911+0000] {task_command.py:423} INFO - Running <TaskInstance: transport_model_training.train_model manual__2025-07-02T14:21:17.805105+00:00 [running]> on host b361e6ed3fa0
[2025-07-02T14:21:20.987+0000] {taskinstance.py:2480} INFO - Exporting env vars: AIRFLOW_CTX_DAG_EMAIL='hamdanialhassangandi2020@gmail.com' AIRFLOW_CTX_DAG_OWNER='ml_team' AIRFLOW_CTX_DAG_ID='transport_model_training' AIRFLOW_CTX_TASK_ID='train_model' AIRFLOW_CTX_EXECUTION_DATE='2025-07-02T14:21:17.805105+00:00' AIRFLOW_CTX_TRY_NUMBER='1' AIRFLOW_CTX_DAG_RUN_ID='manual__2025-07-02T14:21:17.805105+00:00'
[2025-07-02T14:21:20.988+0000] {train_model_dag.py:74} INFO - Running training command: python /opt/***/scripts/train.py --config /opt/***/configs/config.yaml
[2025-07-02T14:21:21.074+0000] {train_model_dag.py:79} ERROR - Training failed: Traceback (most recent call last):
  File "/opt/***/scripts/train.py", line 6, in <module>
    import mlflow
ModuleNotFoundError: No module named 'mlflow'

[2025-07-02T14:21:21.075+0000] {taskinstance.py:2698} ERROR - Task failed with exception
Traceback (most recent call last):
  File "/home/airflow/.local/lib/python3.8/site-packages/airflow/models/taskinstance.py", line 433, in _execute_task
    result = execute_callable(context=context, **execute_callable_kwargs)
  File "/home/airflow/.local/lib/python3.8/site-packages/airflow/operators/python.py", line 199, in execute
    return_value = self.execute_callable()
  File "/home/airflow/.local/lib/python3.8/site-packages/airflow/operators/python.py", line 216, in execute_callable
    return self.python_callable(*self.op_args, **self.op_kwargs)
  File "/opt/airflow/dags/train_model_dag.py", line 75, in train
    result = subprocess.run(cmd, capture_output=True, text=True, check=True, cwd=str(PROJECT_ROOT))
  File "/usr/local/lib/python3.8/subprocess.py", line 516, in run
    raise CalledProcessError(retcode, process.args,
subprocess.CalledProcessError: Command '['python', '/opt/airflow/scripts/train.py', '--config', '/opt/airflow/configs/config.yaml']' returned non-zero exit status 1.
[2025-07-02T14:21:21.085+0000] {taskinstance.py:1138} INFO - Marking task as UP_FOR_RETRY. dag_id=transport_model_training, task_id=train_model, execution_date=20250702T142117, start_date=20250702T142120, end_date=20250702T142121
[2025-07-02T14:21:21.105+0000] {standard_task_runner.py:107} ERROR - Failed to execute job 28 for task train_model (Command '['python', '/opt/airflow/scripts/train.py', '--config', '/opt/airflow/configs/config.yaml']' returned non-zero exit status 1.; 188)
[2025-07-02T14:21:21.117+0000] {local_task_job_runner.py:234} INFO - Task exited with return code 1
[2025-07-02T14:21:21.140+0000] {taskinstance.py:3280} INFO - 0 downstream tasks scheduled from follow-on schedule check
